Workbook

Sheet Návod
A1: Návod
A3: Žlutá buňka = vstup (měň), modrá buňka = výsledek (vzorec). Listy odpovídají záložkám webové pomůcky.
A5: Kabely a jištění: Úbytek a průřez | Pojistka a kabel | Výkon a proud (srovnání 12/24/48 V)
A6: Baterie: Baterie (výdrž, stav nabití, nabíjení, sestavení)
A7: Zdroje a měniče: DC-DC střídač solár
A8: Energetická bilance a LED rezistor.
A9: Tabulky a Checklisty.
A11: Pomůcka je orientační a nenahrazuje údaje výrobce vozidla, baterie ani měniče. Výpočty vždy ověřte.
A12: Tabulka trvalých proudů kabelů (list Data) je konzervativní pro měděné vodiče ve svazku. Pro 48 V používejte pojistky a vypínače s DC napětím ≥ 58 V.
A13: List Data obsahuje pomocné tabulky (průřezy, pojistky, E24), na které se odkazují ostatní listy. Neodstraňujte je.

Sheet Úbytek a průřez
A1: Úbytek a průřez
A2: ΔU = I · ρ · L · k / S; doporučený průřez = max(podle úbytku, podle proudu)
A4: Vstupy | E4: mm² | F4: ΔU % | G4: I max A | H4: OK?
A5: Napětí soustavy | B5: 12 | C5: V | E5: =Data!A3 | F5: =$B$15*$B$16/E5/$B$5*100 | G5: =Data!B3 | H5: =IF(AND(F5<=$B$12,$B$15<=G5),"ano","ne")
A6: Zadání (I = proud, P = výkon) | B6: I | E6: =Data!A4 | F6: =$B$15*$B$16/E6/$B$5*100 | G6: =Data!B4 | H6: =IF(AND(F6<=$B$12,$B$15<=G6),"ano","ne")
A7: Proud (A) / výkon (W) | B7: 30 | E7: =Data!A5 | F7: =$B$15*$B$16/E7/$B$5*100 | G7: =Data!B5 | H7: =IF(AND(F7<=$B$12,$B$15<=G7),"ano","ne")
A8: Délka kabelu (jednosměrně) | B8: 5 | C8: m | E8: =Data!A6 | F8: =$B$15*$B$16/E8/$B$5*100 | G8: =Data!B6 | H8: =IF(AND(F8<=$B$12,$B$15<=G8),"ano","ne")
A9: Zpětný vodič (2 = vlastní kabel, 1 = kostra) | B9: 2 | E9: =Data!A7 | F9: =$B$15*$B$16/E9/$B$5*100 | G9: =Data!B7 | H9: =IF(AND(F9<=$B$12,$B$15<=G9),"ano","ne")
A10: Průřez | B10: 6 | C10: mm² | E10: =Data!A8 | F10: =$B$15*$B$16/E10/$B$5*100 | G10: =Data!B8 | H10: =IF(AND(F10<=$B$12,$B$15<=G10),"ano","ne")
A11: Teplota vodiče | B11: 50 | C11: °C | E11: =Data!A9 | F11: =$B$15*$B$16/E11/$B$5*100 | G11: =Data!B9 | H11: =IF(AND(F11<=$B$12,$B$15<=G11),"ano","ne")
A12: Povolený úbytek | B12: 3 | C12: % | E12: =Data!A10 | F12: =$B$15*$B$16/E12/$B$5*100 | G12: =Data!B10 | H12: =IF(AND(F12<=$B$12,$B$15<=G12),"ano","ne")
E13: =Data!A11 | F13: =$B$15*$B$16/E13/$B$5*100 | G13: =Data!B11 | H13: =IF(AND(F13<=$B$12,$B$15<=G13),"ano","ne")
A14: Výsledky | E14: =Data!A12 | F14: =$B$15*$B$16/E14/$B$5*100 | G14: =Data!B12 | H14: =IF(AND(F14<=$B$12,$B$15<=G14),"ano","ne")
A15: Proud | B15: =IF($B$6="I",$B$7,$B$7/$B$5) | C15: A | E15: =Data!A13 | F15: =$B$15*$B$16/E15/$B$5*100 | G15: =Data!B13 | H15: =IF(AND(F15<=$B$12,$B$15<=G15),"ano","ne")
A16: Odpor smyčky (L · k · ρ / mm²) | B16: =(1/56*(1+0.00393*($B$11-20)))*$B$8*$B$9 | C16: Ω·mm² | E16: =Data!A14 | F16: =$B$15*$B$16/E16/$B$5*100 | G16: =Data!B14 | H16: =IF(AND(F16<=$B$12,$B$15<=G16),"ano","ne")
A17: Úbytek napětí | B17: =$B$15*$B$16/$B$10 | C17: V | E17: =Data!A15 | F17: =$B$15*$B$16/E17/$B$5*100 | G17: =Data!B15 | H17: =IF(AND(F17<=$B$12,$B$15<=G17),"ano","ne")
A18: Úbytek v % | B18: =$B$17/$B$5*100 | C18: % | E18: =Data!A16 | F18: =$B$15*$B$16/E18/$B$5*100 | G18: =Data!B16 | H18: =IF(AND(F18<=$B$12,$B$15<=G18),"ano","ne")
A19: Hodnocení úbytku | B19: =IF($B$18<=$B$12,"OK – vyhovuje","CHYBA – překročeno")
A20: Trvalý proud zvoleného kabelu | B20: =VLOOKUP($B$10,Data!$A$3:$B$16,2,FALSE) | C20: A
A21: Hodnocení proudu | B21: =IF($B$15<=$B$20,"OK – vyhovuje","CHYBA – přetíženo")
A22: Min. průřez podle úbytku | B22: =IFERROR(INDEX(Data!$A$3:$A$16,MATCH(TRUE,INDEX($F$5:$F$18<=$B$12,0),0)),"> 95") | C22: mm²
A23: Min. průřez podle proudu | B23: =IFERROR(INDEX(Data!$A$3:$A$16,MATCH(TRUE,INDEX(Data!$B$3:$B$16>=$B$15,0),0)),"> 95") | C23: mm²
A24: Doporučený průřez | B24: =IF(AND(ISNUMBER($B$22),ISNUMBER($B$23)),MAX($B$22,$B$23),"mimo tabulku") | C24: mm²
A25: Ztráty v kabelu | B25: =$B$15^2*$B$16/$B$10 | C25: W

Sheet Pojistka a kabel
A1: Pojistka a kabel
A2: Pojistka ≥ rezerva × trvalý proud a ≤ zatížitelnost kabelu
A4: Napětí soustavy | B4: 12 | C4: V
A5: Trvalý proud zátěže | B5: 30 | C5: A
A6: Rezerva (×) | B6: 1.25
A7: Délka kabelu (jednosměrně) | B7: 3 | C7: m
A8: Vnitřní odpor baterie | B8: 5 | C8: mΩ
A9: Orientačně: olovo 100 Ah ≈ 5 mΩ na 12 V; LiFePO₄ 100 Ah ≈ 10–20 mΩ na 12 V (násobek pro 24/48 V).
A11: Výsledky
A12: Min. pojistka (I × rezerva) | B12: =$B$5*$B$6 | C12: A
A13: Doporučená pojistka | B13: =IFERROR(INDEX(Data!$D$3:$D$29,MATCH(TRUE,INDEX(Data!$D$3:$D$29>=$B$12,0),0)),"> 500") | C13: A
A14: Kabel pod pojistkou | B14: =IFERROR(INDEX(Data!$A$3:$A$16,MATCH(TRUE,INDEX(Data!$B$3:$B$16>=$B$13,0),0)),"mimo tabulku") | C14: mm²
A15: Typ pojistky | B15: =IF(NOT(ISNUMBER($B$13)),"Class T / jistič",IF($B$13<=40,"plochá (ISO 8820)",IF($B$13<=200,"MIDI / MEGA / ANL","MEGA / ANL / Class T")))
A16: Min. DC napětí pojistky | B16: =IF($B$4<=24,"32 V DC – standardní","58 V DC – speciální")
A17: Odpor kabelu (tam a zpět) | B17: =IFERROR((1/56*(1+0.00393*(20-20)))*$B$7*2/$B$14,0) | C17: Ω
A18: Odhad zkratového proudu | B18: =$B$4/($B$8/1000+$B$17) | C18: A
A19: Pojistka vs. zkrat | B19: =IF($B$18>=5*$B$13,"OK – rychlé vypnutí","POZOR – zkrat vypne pomalu")
A20: Při Isc > 1000 A použij pojistku s dostatečnou vypínací schopností (MEGA, ANL, Class T).

Sheet Výkon a proud
A1: Výkon a proud
A2: P = U·I; R = U²/P; srovnání 12/24/48 V
A4: Výkon ↔ proud ↔ odpor
A5: Napětí | B5: 12 | C5: V
A6: Výkon (vyplň P nebo I) | B6: 600 | C6: W
A7: Proud (volitelně, přepíše P) | C7: A
A8: Účinnost zařízení | B8: 100 | C8: %
A9: Výkon | B9: =IF($B$7<>"",$B$7*$B$5,$B$6) | C9: W
A10: Proud z baterie | B10: =$B$9/($B$5*$B$8/100) | C10: A
A11: Odpor zátěže R = U²/P | B11: =$B$5^2/$B$9 | C11: Ω
A12: Energie za 1 hodinu | B12: =$B$9/($B$8/100)/1000 | C12: kWh
A14: Stejný výkon při 12 / 24 / 48 V
A15: Výkon zátěže | B15: 2000 | C15: W
A16: Délka kabelu (jednosměrně) | B16: 5 | C16: m
A17: Povolený úbytek | B17: 3 | C17: %
A19: Systém V | B19: I (A) | C19: Kabel mm² | D19: Pojistka A
A20: 12 | B20: =$B$15/A20 | C20: =IF(AND(ISNUMBER(IFERROR(INDEX(Data!$A$3:$A$16,MATCH(TRUE,INDEX(B20*(1/56*(1+0.00393*(50-20)))*$B$16*2/Data!$A$3:$A$16/A20*100<=$B$17,0),0)),"> 95")),ISNUMBER(IFERROR(INDEX(Data!$A$3:$A$16,MATCH(TRUE,INDEX(Data!$B$3:$B$16>=B20,0),0)),"> 95"))),MAX(IFERROR(INDEX(Data!$A$3:$A$16,MATCH(TRUE,INDEX(B20*(1/56*(1+0.00393*(50-20)))*$B$16*2/Data!$A$3:$A$16/A20*100<=$B$17,0),0)),"> 95"),IFERROR(INDEX(Data!$A$3:$A$16,MATCH(TRUE,INDEX(Data!$B$3:$B$16>=B20,0),0)),"> 95")),"> 95") | D20: =IFERROR(INDEX(Data!$D$3:$D$29,MATCH(TRUE,INDEX(Data!$D$3:$D$29>=B20*1.25,0),0)),"–")
A21: 24 | B21: =$B$15/A21 | C21: =IF(AND(ISNUMBER(IFERROR(INDEX(Data!$A$3:$A$16,MATCH(TRUE,INDEX(B21*(1/56*(1+0.00393*(50-20)))*$B$16*2/Data!$A$3:$A$16/A21*100<=$B$17,0),0)),"> 95")),ISNUMBER(IFERROR(INDEX(Data!$A$3:$A$16,MATCH(TRUE,INDEX(Data!$B$3:$B$16>=B21,0),0)),"> 95"))),MAX(IFERROR(INDEX(Data!$A$3:$A$16,MATCH(TRUE,INDEX(B21*(1/56*(1+0.00393*(50-20)))*$B$16*2/Data!$A$3:$A$16/A21*100<=$B$17,0),0)),"> 95"),IFERROR(INDEX(Data!$A$3:$A$16,MATCH(TRUE,INDEX(Data!$B$3:$B$16>=B21,0),0)),"> 95")),"> 95") | D21: =IFERROR(INDEX(Data!$D$3:$D$29,MATCH(TRUE,INDEX(Data!$D$3:$D$29>=B21*1.25,0),0)),"–")
A22: 48 | B22: =$B$15/A22 | C22: =IF(AND(ISNUMBER(IFERROR(INDEX(Data!$A$3:$A$16,MATCH(TRUE,INDEX(B22*(1/56*(1+0.00393*(50-20)))*$B$16*2/Data!$A$3:$A$16/A22*100<=$B$17,0),0)),"> 95")),ISNUMBER(IFERROR(INDEX(Data!$A$3:$A$16,MATCH(TRUE,INDEX(Data!$B$3:$B$16>=B22,0),0)),"> 95"))),MAX(IFERROR(INDEX(Data!$A$3:$A$16,MATCH(TRUE,INDEX(B22*(1/56*(1+0.00393*(50-20)))*$B$16*2/Data!$A$3:$A$16/A22*100<=$B$17,0),0)),"> 95"),IFERROR(INDEX(Data!$A$3:$A$16,MATCH(TRUE,INDEX(Data!$B$3:$B$16>=B22,0),0)),"> 95")),"> 95") | D22: =IFERROR(INDEX(Data!$D$3:$D$29,MATCH(TRUE,INDEX(Data!$D$3:$D$29>=B22*1.25,0),0)),"–")

Sheet Baterie
A1: Baterie
A2: Výdrž, stav nabití, nabíjení, sestavení
A4: Výdrž a kapacita
A5: Napětí baterie | B5: 12 | C5: V
A6: Kapacita | B6: 100 | C6: Ah
A7: Využitelná hloubka vybití (olovo 50, LiFePO₄ 80–90) | B7: 50 | C7: %
A8: Zátěž | B8: 200 | C8: W
A9: Účinnost (měnič, ztráty) | B9: 90 | C9: %
A10: Požadovaná výdrž | B10: 10 | C10: h
A11: Energie baterie | B11: =$B$5*$B$6 | C11: Wh
A12: Využitelná energie | B12: =$B$11*$B$7/100 | C12: Wh
A13: Proud z baterie | B13: =$B$8/($B$5*$B$9/100) | C13: A
A14: Výdrž | B14: =$B$12*$B$9/100/$B$8 | C14: h
A15: Potřebná kapacita pro požadovanou výdrž | B15: =$B$8*$B$10/($B$5*$B$7/100*$B$9/100) | C15: Ah
A16: Peukertův efekt (u olova) není započítán.
A18: Stav nabití olověné baterie z napětí (v klidu ≥ 4 h)
A19: Napětí soustavy | B19: 12 | C19: V
A20: Naměřené napětí v klidu | B20: 12.3 | C20: V
A21: Přepočet na 12 V | B21: =$B$20/($B$19/12) | C21: V
A22: Pomocný index | B22: =IF($B$21<=11.8,1,IF($B$21>=12.7,4,MATCH($B$21,Data!$F$3:$F$7,1)))
A23: Stav nabití (odhad) | B23: =IF($B$21<=11.8,0,IF($B$21>=12.7,100,INDEX(Data!$G$3:$G$7,$B$22)+($B$21-INDEX(Data!$F$3:$F$7,$B$22))/(INDEX(Data!$F$3:$F$7,$B$22+1)-INDEX(Data!$F$3:$F$7,$B$22))*(INDEX(Data!$G$3:$G$7,$B$22+1)-INDEX(Data!$G$3:$G$7,$B$22)))) | C23: %
A24: Plně nabitá v klidu | B24: =12.7*$B$19/12 | C24: V
A25: Doporučené odpojení zátěže | B25: =10.5*$B$19/12 | C25: V
A27: Doba nabíjení
A28: Napětí baterie | B28: 12 | C28: V
A29: Kapacita | B29: 100 | C29: Ah
A30: Stav nabití z | B30: 50 | C30: %
A31: Stav nabití na | B31: 100 | C31: %
A32: Nabíjecí proud | B32: 20 | C32: A
A33: Účinnost nabíjení (olovo 85, LiFePO₄ 95) | B33: 85 | C33: %
A34: Nabíjecí napětí | B34: 14.4 | C34: V
A35: Dodat do baterie | B35: =$B$29*($B$31-$B$30)/100 | C35: Ah
A36: Doba nabíjení (orientačně) | B36: =$B$35/($B$33/100*$B$32) | C36: h
A37: Příkon nabíječe | B37: =$B$32*$B$34 | C37: W
A38: C-rate | B38: =$B$32/$B$29 | C38: C
A39: Olovo: poslední ≈ 20 % (absorpce) trvá o hodiny déle.
A41: Sestavení baterie (sériově / paralelně)
A42: Cílové napětí soustavy | B42: 12 | C42: V
A43: Jmenovité napětí článku / bloku | B43: 12 | C43: V
A44: Kapacita jednoho článku / bloku | B44: 100 | C44: Ah
...

Sheet Zdroje a měniče
A1: Zdroje a měniče
A2: DC-DC měnič, střídač 230 V, solární regulátor
A4: DC-DC měnič / nabíječ
A5: Vstupní napětí | B5: 12 | C5: V
A6: Výstupní napětí | B6: 24 | C6: V
A7: Výstupní proud | B7: 20 | C7: A
A8: Účinnost | B8: 92 | C8: %
A9: Výstupní výkon | B9: =$B$6*$B$7 | C9: W
A10: Vstupní proud | B10: =$B$9/($B$5*$B$8/100) | C10: A
A11: Ztráty měniče | B11: =$B$9/($B$8/100)-$B$9 | C11: W
A12: Vstupní pojistka (≥ 1,25 × I) | B12: =IFERROR(INDEX(Data!$D$3:$D$29,MATCH(TRUE,INDEX(Data!$D$3:$D$29>=$B$10*1.25,0),0)),"> 500") | C12: A
A13: Vstupní kabel (podle pojistky) | B13: =IFERROR(INDEX(Data!$A$3:$A$16,MATCH(TRUE,INDEX(Data!$B$3:$B$16>=$B$12,0),0)),"mimo tabulku") | C13: mm²
A15: Střídač 12/24/48 V → 230 V
A16: Napětí baterie | B16: 12 | C16: V
A17: Trvalý výkon AC | B17: 1500 | C17: W
A18: Špičkový výkon AC | B18: 3000 | C18: W
A19: Účinnost střídače | B19: 90 | C19: %
A20: Délka DC kabelu (jednosměrně) | B20: 1.5 | C20: m
A21: Povolený úbytek | B21: 2 | C21: %
A22: Trvalý DC proud | B22: =$B$17/($B$16*$B$19/100) | C22: A
A23: Špičkový DC proud | B23: =$B$18/($B$16*$B$19/100) | C23: A
A24: DC pojistka (≥ 1,25 × I) | B24: =IFERROR(INDEX(Data!$D$3:$D$29,MATCH(TRUE,INDEX(Data!$D$3:$D$29>=$B$22*1.25,0),0)),"> 500") | C24: A
A25: DC kabel (úbytek a pojistka) | B25: =IF(AND(ISNUMBER(IFERROR(INDEX(Data!$A$3:$A$16,MATCH(TRUE,INDEX($B$22*(1/56*(1+0.00393*(50-20)))*$B$20*2/Data!$A$3:$A$16/$B$16*100<=$B$21,0),0)),"> 95")),ISNUMBER(IFERROR(INDEX(Data!$A$3:$A$16,MATCH(TRUE,INDEX(Data!$B$3:$B$16>=$B$24,0),0)),"> 95"))),MAX(IFERROR(INDEX(Data!$A$3:$A$16,MATCH(TRUE,INDEX($B$22*(1/56*(1+0.00393*(50-20)))*$B$20*2/Data!$A$3:$A$16/$B$16*100<=$B$21,0),0)),"> 95"),IFERROR(INDEX(Data!$A$3:$A$16,MATCH(TRUE,INDEX(Data!$B$3:$B$16>=$B$24,0),0)),"> 95")),"mimo tabulku") | C25: mm²
A26: Min. kapacita baterie – LiFePO₄ (1 C) | B26: =$B$22 | C26: Ah
A27: Min. kapacita baterie – olovo (0,2 C) | B27: =$B$22/0.2 | C27: Ah
A29: Solár — MPPT regulátor a výnos
A30: Napětí baterie | B30: 12 | C30: V
A31: Výkon panelů | B31: 400 | C31: Wp
A32: Účinnost regulátoru (MPPT 0,95 / PWM 0,78) | B32: 0.95
A33: Nabíjecí napětí | B33: 14.4 | C33: V
A34: Plné sluneční hodiny / den | B34: 3.5 | C34: h
A35: Voc panelu | B35: 22.5 | C35: V
A36: Panelů v sérii | B36: 2
A37: TK Voc | B37: -0.27 | C37: %/°C
A38: Min. teplota | B38: -15 | C38: °C
A39: Max. PV napětí regulátoru | B39: 100 | C39: V
A40: Nabíjecí proud při špičce | B40: =$B$31*$B$32/$B$33 | C40: A
A41: Regulátor (≥ 1,25 × I) | B41: =IFERROR(INDEX({10,15,20,30,40,50,60,70,80,100,120},MATCH(TRUE,INDEX({10,15,20,30,40,50,60,70,80,100,120}>=$B$40*1.25,0),0)),"> 120") | C41: A
A42: Denní výnos (odhad, ztráty 25 %) | B42: =$B$31*$B$34*0.75 | C42: Wh
A43: Denní výnos v Ah | B43: =$B$42/$B$30 | C43: Ah
...

Sheet Energetická bilance
A1: Energetická bilance
A2: Spotřebič × počet × hodiny za den
A4: Spotřebič | B4: W | C4: h/den | D4: ks | E4: Wh/den | F4: W (zapnuto)
A5: LED osvětlení | B5: 24 | C5: 5 | D5: 1 | E5: =IF(B5="","",B5*C5*D5) | F5: =IF(B5="","",B5*D5)
A6: Kompresorová chladnička | B6: 45 | C6: 8 | D6: 1 | E6: =IF(B6="","",B6*C6*D6) | F6: =IF(B6="","",B6*D6)
A7: Vodní čerpadlo | B7: 60 | C7: 0.3 | D7: 1 | E7: =IF(B7="","",B7*C7*D7) | F7: =IF(B7="","",B7*D7)
A8: Notebook + telefony | B8: 60 | C8: 4 | D8: 1 | E8: =IF(B8="","",B8*C8*D8) | F8: =IF(B8="","",B8*D8)
A9: Ventilátor | B9: 20 | C9: 4 | D9: 1 | E9: =IF(B9="","",B9*C9*D9) | F9: =IF(B9="","",B9*D9)
E10: =IF(B10="","",B10*C10*D10) | F10: =IF(B10="","",B10*D10)
E11: =IF(B11="","",B11*C11*D11) | F11: =IF(B11="","",B11*D11)
E12: =IF(B12="","",B12*C12*D12) | F12: =IF(B12="","",B12*D12)
E13: =IF(B13="","",B13*C13*D13) | F13: =IF(B13="","",B13*D13)
E14: =IF(B14="","",B14*C14*D14) | F14: =IF(B14="","",B14*D14)
E15: =IF(B15="","",B15*C15*D15) | F15: =IF(B15="","",B15*D15)
E16: =IF(B16="","",B16*C16*D16) | F16: =IF(B16="","",B16*D16)
A18: Napětí soustavy | B18: 12 | C18: V
A19: Dní autonomie | B19: 2
A20: Využitelná hloubka vybití (olovo 50, LiFePO₄ 80–90) | B20: 50 | C20: %
A21: Účinnost (měnič, ztráty) | B21: 90 | C21: %
A22: Plné sluneční hodiny / den | B22: 3.5 | C22: h
A23: Spotřeba za den | B23: =SUM(E5:E16) | C23: Wh
A24: Spotřeba za den | B24: =$B$23/$B$18 | C24: Ah
A25: Součet příkonů (vše zapnuto) | B25: =SUM(F5:F16) | C25: W
A26: Součet příkonů (vše zapnuto) | B26: =$B$25/$B$18 | C26: A
A27: Kapacita baterie pro zadané dny | B27: =$B$23*$B$19/($B$18*$B$20/100*$B$21/100) | C27: Ah
A28: Kapacita baterie pro zadané dny | B28: =$B$23*$B$19/($B$20/100*$B$21/100)/1000 | C28: kWh
A29: Solár pro pokrytí denní spotřeby | B29: =$B$23/($B$22*0.75*$B$21/100) | C29: Wp
A30: Počítej s rezervou 20–30 %. V zimě je výnos solárů několikrát nižší.
A32: LED a předřadný rezistor
A33: Napětí zdroje (max., při nabíjení) | B33: 14.4 | C33: V
A34: Úbytek na 1 LED (Vf) | B34: 2 | C34: V
A35: LED v sérii | B35: 3
A36: Proud LED | B36: 20 | C36: mA
A37: Přebytečné napětí | B37: =$B$33-$B$35*$B$34 | C37: V
A38: Vypočtený rezistor | B38: =IF($B$37>0.5,$B$37/($B$36/1000),"málo napětí") | C38: Ω
A39: Pomocné: dekáda | B39: =IF(ISNUMBER($B$38),10^INT(LOG10($B$38)),"")
A40: Nejbližší vyšší z řady E24 | B40: =IF(ISNUMBER($B$38),IFERROR($B$39*INDEX(Data!$I$3:$I$26,MATCH(TRUE,INDEX(Data!$I$3:$I$26*$B$39>=$B$38-0.000000001,0),0)),$B$39*10),"") | C40: Ω
A41: Skutečný proud LED | B41: =IF(ISNUMBER($B$40),$B$37/$B$40*1000,"") | C41: mA
A42: Ztráta na rezistoru | B42: =IF(ISNUMBER($B$40),($B$41/1000)^2*$B$40*1000,"") | C42: mW
A43: Min. výkon rezistoru = 2 × ztráta. U 24/48 V zapoj více LED do série nebo použij proudový zdroj.

Sheet Tabulky
A1: Tabulky
A3: Typická napětí podle soustavy (násobek pro 12/24/48 V) | F3: Barva pojistky (ISO 8820) | G3: A
B4: 12 V | C4: 24 V | D4: 48 V | F4: černá | G4: 1
A5: Olovo: plně nabité v klidu | B5: =12.7*1 | C5: =12.7*2 | D5: =12.7*4 | F5: šedá | G5: 2
A6: Olovo: absorpce (typ. min) | B6: =14.4*1 | C6: =14.4*2 | D6: =14.4*4 | F6: fialová | G6: 3
A7: Olovo: absorpce (typ. max) | B7: =14.8*1 | C7: =14.8*2 | D7: =14.8*4 | F7: růžová | G7: 4
A8: Olovo: float (typ.) | B8: =13.6*1 | C8: =13.6*2 | D8: =13.6*4 | F8: béžová | G8: 5
A9: Olovo: odpojení zátěže | B9: =10.5*1 | C9: =10.5*2 | D9: =10.5*4 | F9: hnědá | G9: 7.5
A10: LiFePO₄: jmenovité (4S/8S/16S) | B10: =12.8*1 | C10: =12.8*2 | D10: =12.8*4 | F10: červená | G10: 10
A11: LiFePO₄: nabíjení (min) | B11: =14.2*1 | C11: =14.2*2 | D11: =14.2*4 | F11: světle modrá | G11: 15
A12: LiFePO₄: nabíjení (max) | B12: =14.6*1 | C12: =14.6*2 | D12: =14.6*4 | F12: žlutá | G12: 20
A13: LiFePO₄: odpojení (min) | B13: =10*1 | C13: =10*2 | D13: =10*4 | F13: bílá / čirá | G13: 25
A14: LiFePO₄: odpojení (max) | B14: =11*1 | C14: =11*2 | D14: =11*4 | F14: zelená | G14: 30
F15: oranžová | G15: 40
A16: Průřez → trvalý proud → max. pojistka
A17: mm² | B17: I trvalý A | C17: max pojistka A | F17: Značení svorek (DIN 72552)
A18: =Data!A3 | B18: =Data!B3 | C18: =IFERROR(LOOKUP(B18,Data!$D$3:$D$29),"–") | F18: Svorka | G18: Význam
A19: =Data!A4 | B19: =Data!B4 | C19: =IFERROR(LOOKUP(B19,Data!$D$3:$D$29),"–") | F19: 30 | G19: trvalé + z baterie
A20: =Data!A5 | B20: =Data!B5 | C20: =IFERROR(LOOKUP(B20,Data!$D$3:$D$29),"–") | F20: 31 | G20: kostra (−)
A21: =Data!A6 | B21: =Data!B6 | C21: =IFERROR(LOOKUP(B21,Data!$D$3:$D$29),"–") | F21: 15 | G21: + po zapalování
A22: =Data!A7 | B22: =Data!B7 | C22: =IFERROR(LOOKUP(B22,Data!$D$3:$D$29),"–") | F22: 50 | G22: startér
A23: =Data!A8 | B23: =Data!B8 | C23: =IFERROR(LOOKUP(B23,Data!$D$3:$D$29),"–") | F23: 56 / 58 | G23: hlavní / obrysová světla
A24: =Data!A9 | B24: =Data!B9 | C24: =IFERROR(LOOKUP(B24,Data!$D$3:$D$29),"–") | F24: 49 / 49a | G24: vstup / výstup směrovek
A25: =Data!A10 | B25: =Data!B10 | C25: =IFERROR(LOOKUP(B25,Data!$D$3:$D$29),"–") | F25: 61 | G25: kontrolka nabíjení
A26: =Data!A11 | B26: =Data!B11 | C26: =IFERROR(LOOKUP(B26,Data!$D$3:$D$29),"–") | F26: 85 / 86 | G26: relé: cívka
A27: =Data!A12 | B27: =Data!B12 | C27: =IFERROR(LOOKUP(B27,Data!$D$3:$D$29),"–") | F27: 30 | G27: relé: společný
A28: =Data!A13 | B28: =Data!B13 | C28: =IFERROR(LOOKUP(B28,Data!$D$3:$D$29),"–") | F28: 87 / 87a | G28: relé: NO / NC
A29: =Data!A14 | B29: =Data!B14 | C29: =IFERROR(LOOKUP(B29,Data!$D$3:$D$29),"–")
A30: =Data!A15 | B30: =Data!B15 | C30: =IFERROR(LOOKUP(B30,Data!$D$3:$D$29),"–")
A31: =Data!A16 | B31: =Data!B16 | C31: =IFERROR(LOOKUP(B31,Data!$D$3:$D$29),"–")
A34: AWG → mm²
A35: AWG | B35: Ø mm | C35: mm²
A36: 24 | B36: =0.127*92^((36-24)/39) | C36: =PI()/4*B36^2
A37: 22 | B37: =0.127*92^((36-22)/39) | C37: =PI()/4*B37^2
A38: 20 | B38: =0.127*92^((36-20)/39) | C38: =PI()/4*B38^2
A39: 18 | B39: =0.127*92^((36-18)/39) | C39: =PI()/4*B39^2
A40: 16 | B40: =0.127*92^((36-16)/39) | C40: =PI()/4*B40^2
A41: 14 | B41: =0.127*92^((36-14)/39) | C41: =PI()/4*B41^2
A42: 12 | B42: =0.127*92^((36-12)/39) | C42: =PI()/4*B42^2
A43: 10 | B43: =0.127*92^((36-10)/39) | C43: =PI()/4*B43^2
...

Sheet Check nový okruh
A1: Check nový okruh
A2: Instalace nového spotřebiče / okruhu
A4: Bod | B4: Splněno (x) | C4: Poznámka
A5: Určen trvalý a špičkový proud spotřebiče
A6: Pojistka nebo jistič co nejblíž ke zdroji (baterii), dimenzovaná na kabel
A7: Průřez zkontrolován na úbytek napětí i na trvalý proud
A8: Kabel odolný teplu a oděru, ochranný vlnovec, průchodky v plechu
A9: Kvalitní lisované koncovky a spoje, správná velikost oka
A10: Velké zátěže spínány přes relé / stykač
A11: Kostrový spoj čistý, kov na kov, zajištěn proti uvolnění
A12: Spoje utaženy předepsaným momentem, svorky zakryty proti zkratu
A13: Změřen úbytek napětí na plus i mínus pod zátěží
A14: Zákres do schématu, kabely označeny
A16: ="Splněno "&COUNTIF(B5:B14,"x")&" z 10"

Sheet Check diagnostika
A1: Check diagnostika
A2: Diagnostika baterie a nabíjení (12 V, u 24/48 V násobky)
A4: Bod | B4: Splněno (x) | C4: Poznámka
A5: Vizuálně: svorky, koroze, uchycení, oleje, zápach
A6: Napětí v klidu (po ≥ 4 h): ≥ 12,4 V (24 V: 24,8 V)
A7: Při startu napětí nesmí klesnout pod ≈ 9,6 V (24 V: 19,2 V)
A8: Napětí při běžícím motoru: 13,8–14,8 V (24 V: 27,6–29,6 V)
A9: Úbytek napětí na kladném kabelu při startu: < 0,5 V
A10: Úbytek napětí na kostře při startu: < 0,3 V
A11: Klidový odběr po uspání vozidla: typicky < 50 mA (dle výrobce)
A12: Zvlnění alternátoru (AC) při chodu: < 0,5 V
A13: Alternátor, řemen a pojistky nabíjecího okruhu OK
A15: ="Splněno "&COUNTIF(B5:B13,"x")&" z 9"

Sheet Check ostrovní systém
A1: Check ostrovní systém
A2: Ostrovní systém 12/24/48 V (karavan, loď, dodávka)
A4: Bod | B4: Splněno (x) | C4: Poznámka
A5: Baterie s vhodným BMS / ochranami, ventilace u olova
A6: Hlavní pojistka (MEGA / Class T) a hlavní vypínač u baterie
A7: Pro 48 V: pojistky, vypínače a relé s jmenovitým DC napětím ≥ 58 V
A8: Samostatná pojistka na každou větev paralelních baterií
A9: Měření (shunt, BMS) zapojeno, nastavena kapacita a napětí
A10: Solární regulátor nastaven na typ baterie, kontrola Voc za mrazu
A11: Střídač: DC kabel krátký a dostatečný, pojistka u baterie
A12: AC strana: RCD/jistič, ochrana a uzemnění dle typu aplikace
A13: Společná kostra / záporná sběrnice, jedno místo spojení s kostrou
A14: Polarita a štítky na všech vodičích, zkušební zapnutí po částech
A15: Zátěžový test: výdrž, úbytky, teploty spojů
A17: ="Splněno "&COUNTIF(B5:B15,"x")&" z 11"

Sheet Data
A1: Data
A2: mm² | B2: I trvalý A | D2: Pojistky A | F2: SOC V (12 V) | G2: SOC % | I2: E24
A3: 0.5 | B3: 5 | D3: 1 | F3: 11.8 | G3: 0 | I3: 1
A4: 0.75 | B4: 8 | D4: 2 | F4: 12 | G4: 25 | I4: 1.1
A5: 1 | B5: 10 | D5: 3 | F5: 12.2 | G5: 50 | I5: 1.2
A6: 1.5 | B6: 14 | D6: 4 | F6: 12.5 | G6: 75 | I6: 1.3
A7: 2.5 | B7: 20 | D7: 5 | F7: 12.7 | G7: 100 | I7: 1.5
A8: 4 | B8: 28 | D8: 7.5 | I8: 1.6
A9: 6 | B9: 36 | D9: 10 | I9: 1.8
A10: 10 | B10: 50 | D10: 15 | I10: 2
A11: 16 | B11: 70 | D11: 20 | I11: 2.2
A12: 25 | B12: 95 | D12: 25 | I12: 2.4
A13: 35 | B13: 120 | D13: 30 | I13: 2.7
A14: 50 | B14: 150 | D14: 35 | I14: 3
A15: 70 | B15: 190 | D15: 40 | I15: 3.3
A16: 95 | B16: 230 | D16: 50 | I16: 3.6
D17: 60 | I17: 3.9
D18: 70 | I18: 4.3
D19: 80 | I19: 4.7
D20: 100 | I20: 5.1
D21: 125 | I21: 5.6
D22: 150 | I22: 6.2
D23: 175 | I23: 6.8
D24: 200 | I24: 7.5
D25: 250 | I25: 8.2
D26: 300 | I26: 9.1
D27: 350
D28: 400
D29: 500
